Workbook

Sheet List chi tiet
A2: Tên Công Trình: | B2: 10626-051 DG SÂN VẬN ĐỘNG HÙNG VƯƠNG | L2: LIST CHI TIẾT CẤU KIỆN
A3: Mã Dự Án: | B3: =INDEX(V6:V100041, MATCH(1, INDEX(SUBTOTAL(3, OFFSET(V6, ROW(V6:V100041)-ROW(V6), 0)), 0), 0)) -> 10626-051
A4: Building No. : | B4: =INDEX(Z6:Z99999, MATCH(1, INDEX(SUBTOTAL(3, OFFSET(Z6, ROW(Z6:Z99999)-ROW(Z6), 0)), 0), 0)) -> GIAN NANG 3A-UT1 | G4: =SUMPRODUCT(G6:G99999, H6:H99999, SUBTOTAL(103, OFFSET(G6, ROW(G6:G99999)-ROW(G6), 0))) -> 1905201.2 | H4: =SUMPRODUCT(SUBTOTAL(109, OFFSET(H6, ROW(H6:H99995)-ROW(H6), 0)), (B6:B99995<>"") * (B6:B99995<>0)) -> 1306 | J4: =SUMPRODUCT(SUBTOTAL(109, OFFSET(J6, ROW(J6:J99995)-ROW(J6), 0)), (B6:B99995<>"") * (B6:B99995<>0)) -> 150089.75 | L4: =SUMPRODUCT(SUBTOTAL(103, OFFSET(B6, ROW(B6:B99996)-ROW(B6), 0))) -> 436
A5: STT | B5: Tên chi tiết | C5: Mác thép | D5: Quy.Cách.Part | E5: Dày | F5: Rộng | G5: Dài | H5: Qty | I5: KL chi tiết | J5: KL Tổng | K5: Quy Cách Vật Tư | L5: Số Nesting | M5: Cutting | N5: Khoan | O5: Chấn | P5: Vát mép | Q5: Lần-BH | R5: Ngày B.Hành | S5: Note | T5: REV01 | U5: REV02 | V5: Mã Dự Án | W5: TC | X5: BM | Y5: CB | Z5: Hạng Mục | AA5: Nguồn Gốc Vật Tư | AB5: =$B$2 -> 10626-051 DG SÂN VẬN ĐỘNG HÙNG VƯƠNG
A6: 1 | B6: BA1 | C6: Q355 | D6: PL25x80x12000 | E6: 25 | F6: 80 | G6: 12000 | H6: 12 | I6: 188.4 | J6: 2260.8 | K6: PL25x2200x12000 | L6: VT-HV-TT-001-CHANPINX30/Y21-Y22-Q355-SP25-001 | Q6: 1 | R6: 06/07/2026 | T6: REV01 | V6: 10626-051 | Z6: PIN MB1 PIN2 (X30/Y21-Y22) | AA6: NEWPLATE
A7: 2 | B7: BA2 | C7: Q355 | D7: PL25x50x12000 | E7: 25 | F7: 50 | G7: 12000 | H7: 1 | I7: 117.75 | J7: 117.75 | K7: PL25x2200x12000 | L7: VT-HV-TT-001-CHANPINX30/Y21-Y22-Q355-SP25-001 | Q7: 1 | R7: 06/07/2026 | T7: REV01 | V7: 10626-051 | Z7: PIN MB1 PIN2 (X30/Y21-Y22) | AA7: NEWPLATE
A8: 3 | B8: LP1-0002-Z1-PH1-0038-K | C8: Q355 | D8: PL30x180x800 | E8: 30 | F8: 180 | G8: 800 | H8: 77 | I8: 31.49 | J8: 2425.11 | K8: PL30x2000x12000 | L8: VT-HV-TT-001-CHANPINX30/Y21-Y22-Q355-SP30-001 | N8: K | Q8: 1 | R8: 06/07/2026 | V8: 10626-051 | X8: X | Z8: PIN MB1 PIN2 (X30/Y21-Y22) | AA8: NEWPLATE
A9: 4 | B9: PIN1-0022-Z1-PH1-0037-K | C9: Q355 | D9: PL30x230x300 | E9: 30 | F9: 230 | G9: 300 | H9: 52 | I9: 15.04 | J9: 782.13 | K9: PL30x2000x12000 | L9: VT-HV-TT-001-CHANPINX30/Y21-Y22-Q355-SP30-001 | N9: K | Q9: 1 | R9: 06/07/2026 | V9: 10626-051 | X9: X | Z9: PIN MB1 PIN2 (X30/Y21-Y22) | AA9: NEWPLATE
A10: 5 | B10: PIN1-0017-Z1-PH1-0037-K | C10: Q355 | D10: PL30x230x300 | E10: 30 | F10: 230 | G10: 300 | H10: 52 | I10: 15.04 | J10: 782.13 | K10: PL30x2000x12000 | L10: VT-HV-TT-001-CHANPINX30/Y21-Y22-Q355-SP30-001 | N10: K | Q10: 1 | R10: 06/07/2026 | V10: 10626-051 | X10: X | Z10: PIN MB1 PIN2 (X30/Y21-Y22) | AA10: NEWPLATE
A11: 6 | B11: BRP1-0013-Z1-PH1-0037-K | C11: Q355 | D11: PL30x230x300 | E11: 30 | F11: 230 | G11: 300 | H11: 6 | I11: 15.04 | J11: 90.25 | K11: PL30x2000x12000 | L11: VT-HV-TT-001-CHANPINX30/Y21-Y22-Q355-SP30-001 | N11: K | Q11: 1 | R11: 06/07/2026 | V11: 10626-051 | X11: X | Z11: PIN MB1 PIN2 (X30/Y21-Y22) | AA11: NEWPLATE
A12: 7 | B12: PIN1-0021-Z1-PH1-0037-K | C12: Q355 | D12: PL30x230x300 | E12: 30 | F12: 230 | G12: 300 | H12: 32 | I12: 15.04 | J12: 481.31 | K12: PL30x2000x12000 | L12: VT-HV-TT-001-CHANPINX30/Y21-Y22-Q355-SP30-001 | N12: K | Q12: 1 | R12: 06/07/2026 | V12: 10626-051 | X12: X | Z12: PIN MB1 PIN2 (X30/Y21-Y22) | AA12: NEWPLATE
A13: 8 | B13: PIN1-0019-Z1-PH1-0037-K | C13: Q355 | D13: PL30x230x300 | E13: 30 | F13: 230 | G13: 300 | H13: 31 | I13: 15.04 | J13: 466.27 | K13: PL30x2000x12000 | L13: VT-HV-TT-001-CHANPINX30/Y21-Y22-Q355-SP30-001 | N13: K | Q13: 1 | R13: 06/07/2026 | V13: 10626-051 | X13: X | Z13: PIN MB1 PIN2 (X30/Y21-Y22) | AA13: NEWPLATE
A14: 9 | B14: LP1-0002-Z1-PH1-0038-K | C14: Q355 | D14: PL30x180x800 | E14: 30 | F14: 180 | G14: 800 | H14: 87 | I14: 31.49 | J14: 2740.06 | K14: PL30x2000x12000 | L14: VT-HV-TT-001-CHANPINX30/Y21-Y22-Q355-SP30-002 | N14: K | Q14: 1 | R14: 06/07/2026 | V14: 10626-051 | X14: X | Z14: PIN MB1 PIN2 (X30/Y21-Y22) | AA14: NEWPLATE
A15: 10 | B15: PIN1-0019-Z1-PH1-0037-K | C15: Q355 | D15: PL30x230x300 | E15: 30 | F15: 230 | G15: 300 | H15: 1 | I15: 15.04 | J15: 15.04 | K15: PL30x2000x12000 | L15: VT-HV-TT-001-CHANPINX30/Y21-Y22-Q355-SP30-002 | N15: K | Q15: 1 | R15: 06/07/2026 | V15: 10626-051 | X15: X | Z15: PIN MB1 PIN2 (X30/Y21-Y22) | AA15: NEWPLATE
A16: 11 | B16: BRP1-0007-Z1-PH1-0037-K | C16: Q355 | D16: PL30x230x300 | E16: 30 | F16: 230 | G16: 300 | H16: 48 | I16: 15.04 | J16: 721.97 | K16: PL30x2000x12000 | L16: VT-HV-TT-001-CHANPINX30/Y21-Y22-Q355-SP30-002 | N16: K | Q16: 1 | R16: 06/07/2026 | V16: 10626-051 | X16: X | Z16: PIN MB1 PIN2 (X30/Y21-Y22) | AA16: NEWPLATE
A17: 12 | B17: BRP1-0005-Z1-PH1-0037-K | C17: Q355 | D17: PL30x230x300 | E17: 30 | F17: 230 | G17: 300 | H17: 24 | I17: 15.04 | J17: 360.98 | K17: PL30x2000x12000 | L17: VT-HV-TT-001-CHANPINX30/Y21-Y22-Q355-SP30-002 | N17: K | Q17: 1 | R17: 06/07/2026 | V17: 10626-051 | X17: X | Z17: PIN MB1 PIN2 (X30/Y21-Y22) | AA17: NEWPLATE
A18: 13 | B18: BRP1-0003-Z1-PH1-0037-K | C18: Q355 | D18: PL30x230x300 | E18: 30 | F18: 230 | G18: 300 | H18: 24 | I18: 15.04 | J18: 360.98 | K18: PL30x2000x12000 | L18: VT-HV-TT-001-CHANPINX30/Y21-Y22-Q355-SP30-002 | N18: K | Q18: 1 | R18: 06/07/2026 | V18: 10626-051 | X18: X | Z18: PIN MB1 PIN2 (X30/Y21-Y22) | AA18: NEWPLATE
A19: 14 | B19: BRP1-0012-Z1-PH1-0037-K | C19: Q355 | D19: PL30x230x300 | E19: 30 | F19: 230 | G19: 300 | H19: 24 | I19: 15.04 | J19: 360.98 | K19: PL30x2000x12000 | L19: VT-HV-TT-001-CHANPINX30/Y21-Y22-Q355-SP30-002 | N19: K | Q19: 1 | R19: 06/07/2026 | V19: 10626-051 | X19: X | Z19: PIN MB1 PIN2 (X30/Y21-Y22) | AA19: NEWPLATE
... A28: 23 | B28: PIN1-0022-Z1-PH1-0042-K | C28: Q355 | D28: PL40x230x300 | E28: 40 | F28: 230 | G28: 300 | H28: 8 | I28: 20.06 | J28: 160.44 | K28: PL40x2500x12000 | L28: VT-HV-TT-001-CHANPINX30/Y21-Y22-Q355-SP40-001 | N28: K | Q28: 1 | R28: 06/07/2026 | V28: 10626-051 | X28: X | Z28: PIN MB1 PIN2 (X30/Y21-Y22) | AA28: NEWPLATE
A29: 24 | B29: BRP1-0001-Z1-PL1-0036 | C29: Q355B | D29: PL80x260x436 | E29: 80 | F29: 260 | G29: 436 | H29: 1 | I29: 69.98 | J29: 69.98 | K29: PL80x2750x12000 | L29: VT-HV-TT-001-CHANPINX30/Y21-Y22-Q355-SP80-001 | Q29: 1 | R29: 06/07/2026 | T29: REV01 | V29: 10626-051 | W29: X | Z29: PIN MB1 PIN2 (X30/Y21-Y22) | AA29: NEWPLATE
A30: 25 | B30: LPP1-0011-Z1-PLP1-0001-V | C30: Q355B | D30: PL80x180x500 | E30: 80 | F30: 180 | G30: 500 | H30: 2 | I30: 42.1 | J30: 84.2 | K30: PL80x2750x12000 | L30: VT-HV-TT-001-CHANPINX30/Y21-Y22-Q355-SP80-001 | P30: X | Q30: 1 | R30: 06/07/2026 | T30: REV01 | V30: 10626-051 | W30: X | Z30: PIN MB1 PIN2 (X30/Y21-Y22) | AA30: NEWPLATE
A31: 26 | B31: PIN1-0021-Z1-PL1-0008 | C31: Q355B | D31: PL80x180x500 | E31: 80 | F31: 180 | G31: 500 | H31: 1 | I31: 42.1 | J31: 42.1 | K31: PL80x2750x12000 | L31: VT-HV-TT-001-CHANPINX30/Y21-Y22-Q355-SP80-001 | Q31: 1 | R31: 06/07/2026 | T31: REV01 | V31: 10626-051 | W31: X | Z31: PIN MB1 PIN2 (X30/Y21-Y22) | AA31: NEWPLATE
A32: 27 | B32: PIN1-0021-Z1-PL1-0041 | C32: Q355B | D32: PL80x400x800 | E32: 80 | F32: 400 | G32: 800 | H32: 1 | I32: 200.96 | J32: 200.96 | K32: PL80x2750x12000 | L32: VT-HV-TT-001-CHANPINX30/Y21-Y22-Q355-SP80-001 | Q32: 1 | R32: 06/07/2026 | T32: REV01 | V32: 10626-051 | W32: X | Z32: PIN MB1 PIN2 (X30/Y21-Y22) | AA32: NEWPLATE
A33: 28 | B33: PIN1-0022-Z1-FL1-0029-V | C33: Q355B | D33: PL80x600x958 | E33: 80 | F33: 600 | G33: 958 | H33: 2 | I33: 360.98 | J33: 721.95 | K33: PL80x2750x12000 | L33: VT-HV-TT-001-CHANPINX30/Y21-Y22-Q355-SP80-001 | P33: X | Q33: 1 | R33: 06/07/2026 | T33: REV01 | V33: 10626-051 | Y33: X | Z33: PIN MB1 PIN2 (X30/Y21-Y22) | AA33: NEWPLATE
A34: 29 | B34: PIN1-0022-Z1-FL1-0032-V | C34: Q355B | D34: PL80x600x1413 | E34: 80 | F34: 600 | G34: 1413 | H34: 2 | I34: 532.42 | J34: 1064.84 | K34: PL80x2750x12000 | L34: VT-HV-TT-001-CHANPINX30/Y21-Y22-Q355-SP80-001 | P34: X | Q34: 1 | R34: 06/07/2026 | T34: REV01 | V34: 10626-051 | Y34: X | Z34: PIN MB1 PIN2 (X30/Y21-Y22) | AA34: NEWPLATE
A35: 30 | B35: PIN1-0022-Z1-PL1-0008 | C35: Q355B | D35: PL80x180x500 | E35: 80 | F35: 180 | G35: 500 | H35: 1 | I35: 42.1 | J35: 42.1 | K35: PL80x2750x12000 | L35: VT-HV-TT-001-CHANPINX30/Y21-Y22-Q355-SP80-001 | Q35: 1 | R35: 06/07/2026 | T35: REV01 | V35: 10626-051 | W35: X | Z35: PIN MB1 PIN2 (X30/Y21-Y22) | AA35: NEWPLATE
A36: 31 | B36: PIN1-0022-Z1-PL1-0017 | C36: Q355B | D36: PL80x350x2200 | E36: 80 | F36: 350 | G36: 2200 | H36: 5 | I36: 454.07 | J36: 2270.33 | K36: PL80x2750x12000 | L36: VT-HV-TT-001-CHANPINX30/Y21-Y22-Q355-SP80-001 | Q36: 1 | R36: 06/07/2026 | T36: REV01 | V36: 10626-051 | W36: X | Z36: PIN MB1 PIN2 (X30/Y21-Y22) | AA36: NEWPLATE
A37: 32 | B37: PIN1-0022-Z1-PL1-0033 | C37: Q355B | D37: PL80x500x1396 | E37: 80 | F37: 500 | G37: 1396 | H37: 2 | I37: 438.34 | J37: 876.69 | K37: PL80x2750x12000 | L37: VT-HV-TT-001-CHANPINX30/Y21-Y22-Q355-SP80-001 | Q37: 1 | R37: 06/07/2026 | T37: REV01 | V37: 10626-051 | W37: X | Z37: PIN MB1 PIN2 (X30/Y21-Y22) | AA37: NEWPLATE
A38: 33 | B38: PIN1-0022-Z1-PL1-0045 | C38: Q355B | D38: PL80x1007x2200 | E38: 80 | F38: 1007 | G38: 2200 | H38: 3 | I38: 1258.16 | J38: 3774.47 | K38: PL80x2750x12000 | L38: VT-HV-TT-001-CHANPINX30/Y21-Y22-Q355-SP80-001 | Q38: 1 | R38: 06/07/2026 | T38: REV01 | V38: 10626-051 | W38: X | Z38: PIN MB1 PIN2 (X30/Y21-Y22) | AA38: NEWPLATE
A39: 34 | B39: PIN1-0022-Z1-PL1-0046 | C39: Q355B | D39: PL80x400x600 | E39: 80 | F39: 400 | G39: 600 | H39: 1 | I39: 150.72 | J39: 150.72 | K39: PL80x2750x12000 | L39: VT-HV-TT-001-CHANPINX30/Y21-Y22-Q355-SP80-001 | Q39: 1 | R39: 06/07/2026 | T39: REV01 | V39: 10626-051 | W39: X | Z39: PIN MB1 PIN2 (X30/Y21-Y22) | AA39: NEWPLATE
A40: 35 | B40: PIN1-0022-Z1-PL1-0047 | C40: Q355B | D40: PL80x400x927 | E40: 80 | F40: 400 | G40: 927 | H40: 1 | I40: 227.93 | J40: 227.93 | K40: PL80x2750x12000 | L40: VT-HV-TT-001-CHANPINX30/Y21-Y22-Q355-SP80-001 | Q40: 1 | R40: 06/07/2026 | T40: REV01 | V40: 10626-051 | W40: X | Z40: PIN MB1 PIN2 (X30/Y21-Y22) | AA40: NEWPLATE
A41: 36 | B41: PIN1-0022-Z1-PL1-0078 | C41: Q355B | D41: PL80x790x2200 | E41: 80 | F41: 790 | G41: 2200 | H41: 3 | I41: 1061.97 | J41: 3185.91 | K41: PL80x2750x12000 | L41: VT-HV-TT-001-CHANPINX30/Y21-Y22-Q355-SP80-001 | Q41: 1 | R41: 06/07/2026 | T41: REV01 | V41: 10626-051 | W41: X | Z41: PIN MB1 PIN2 (X30/Y21-Y22) | AA41: NEWPLATE
A42: 37 | B42: PIN1-0022-Z1-PL1-0079 | C42: Q355B | D42: PL80x400x790 | E42: 80 | F42: 400 | G42: 790 | H42: 1 | I42: 195.98 | J42: 195.98 | K42: PL80x2750x12000 | L42: VT-HV-TT-001-CHANPINX30/Y21-Y22-Q355-SP80-001 | Q42: 1 | R42: 06/07/2026 | T42: REV01 | V42: 10626-051 | W42: X | Z42: PIN MB1 PIN2 (X30/Y21-Y22) | AA42: NEWPLATE
A43: 38 | B43: PIN1-0022-Z1-PL1-0080 | C43: Q355B | D43: PL80x600x790 | E43: 80 | F43: 600 | G43: 790 | H43: 1 | I43: 268.18 | J43: 268.18 | K43: PL80x2750x12000 | L43: VT-HV-TT-001-CHANPINX30/Y21-Y22-Q355-SP80-001 | Q43: 1 | R43: 06/07/2026 | T43: REV01 | V43: 10626-051 | W43: X | Z43: PIN MB1 PIN2 (X30/Y21-Y22) | AA43: NEWPLATE
A44: 39 | B44: PIN1-0022-Z1-PL1-0082 | C44: Q355B | D44: PL80x350x400 | E44: 80 | F44: 350 | G44: 400 | H44: 1 | I44: 85.45 | J44: 85.45 | K44: PL80x2750x12000 | L44: VT-HV-TT-001-CHANPINX30/Y21-Y22-Q355-SP80-001 | Q44: 1 | R44: 06/07/2026 | T44: REV01 | V44: 10626-051 | W44: X | Z44: PIN MB1 PIN2 (X30/Y21-Y22) | AA44: NEWPLATE
A45: 40 | B45: PIN1-0022-Z1-W1-0029-V | C45: Q355B | D45: PL80x440x1413 | E45: 80 | F45: 440 | G45: 1413 | H45: 1 | I45: 333.02 | J45: 333.02 | K45: PL80x2750x12000 | L45: VT-HV-TT-001-CHANPINX30/Y21-Y22-Q355-SP80-001 | P45: X | Q45: 1 | R45: 06/07/2026 | T45: REV01 | V45: 10626-051 | Y45: X | Z45: PIN MB1 PIN2 (X30/Y21-Y22) | AA45: NEWPLATE
A46: 41 | B46: PIN1-0022-Z1-W1-0040-V | C46: Q355B | D46: PL80x960x1498 | E46: 80 | F46: 960 | G46: 1498 | H46: 2 | I46: 896.42 | J46: 1792.85 | K46: PL80x2750x12000 | L46: VT-HV-TT-001-CHANPINX30/Y21-Y22-Q355-SP80-001 | P46: X | Q46: 1 | R46: 06/07/2026 | T46: REV01 | V46: 10626-051 | Y46: X | Z46: PIN MB1 PIN2 (X30/Y21-Y22) | AA46: NEWPLATE
A47: 42 | B47: PIN1-0022-Z1-W1-0042-V | C47: Q355B | D47: PL80x960x1311 | E47: 80 | F47: 960 | G47: 1311 | H47: 2 | I47: 783.68 | J47: 1567.37 | K47: PL80x2750x12000 | L47: VT-HV-TT-001-CHANPINX30/Y21-Y22-Q355-SP80-001 | P47: X | Q47: 1 | R47: 06/07/2026 | T47: REV01 | V47: 10626-051 | Y47: X | Z47: PIN MB1 PIN2 (X30/Y21-Y22) | AA47: NEWPLATE
A48: 43 | B48: PIN1-0022-Z1-W1-0044-V | C48: Q355B | D48: PL80x960x1528 | E48: 80 | F48: 960 | G48: 1528 | H48: 2 | I48: 909.58 | J48: 1819.16 | K48: PL80x2750x12000 | L48: VT-HV-TT-001-CHANPINX30/Y21-Y22-Q355-SP80-001 | P48: X | Q48: 1 | R48: 06/07/2026 | T48: REV01 | V48: 10626-051 | Y48: X | Z48: PIN MB1 PIN2 (X30/Y21-Y22) | AA48: NEWPLATE
A49: 44 | B49: PIN1-0022-Z1-W1-0182-V | C49: Q355B | D49: PL80x440x1413 | E49: 80 | F49: 440 | G49: 1413 | H49: 1 | I49: 333.02 | J49: 333.02 | K49: PL80x2750x12000 | L49: VT-HV-TT-001-CHANPINX30/Y21-Y22-Q355-SP80-001 | P49: X | Q49: 1 | R49: 06/07/2026 | T49: REV01 | V49: 10626-051 | Y49: X | Z49: PIN MB1 PIN2 (X30/Y21-Y22) | AA49: NEWPLATE
...

Sheet Phieu vat tu
N1: =IF(J1<>"",J1*I1*H1*7.85/10^6,"") | P1: =IF(J1<>"",J1*I1*H1*7.85/10^6,"") | Q1: =IF(O1="NEWPLATE", N1, "") | R1: =IF(O1<>"NEWPLATE", N1, "") | T1: =IFERROR(MAX(ROUND(N1-P1-IF(S1="",0,S1)-U1, 2), 0),"") | U1: =IFERROR(ROUND(P1*0.7/100, 2),"") | W1: =IFERROR(IF(A1="No STT","Lệnh Sản Xuất",LEFT(C1,FIND("#",SUBSTITUTE(C1,"-","#",4))-1)),"")
G2: ="Phiếu Yêu Cầu Vật Tư - "&IFERROR(LEFT(INDEX(C5:C99971,MATCH(1,INDEX(SUBTOTAL(3,OFFSET(C5,ROW(C5:C99971)-ROW(C5),0)),0),0)),FIND("#",SUBSTITUTE(INDEX(C5:C99971,MATCH(1,INDEX(SUBTOTAL(3,OFFSET(C5,ROW(C5:C99971)-ROW(C5),0)),0),0)),"-","#",4))-1),"") -> Phiếu Yêu Cầu Vật Tư - VT-HV-TT-085 | W2: =IFERROR(IF(A2="No STT","Lệnh Sản Xuất",INDEX(W5:W99971, MATCH(1, INDEX(SUBTOTAL(3, OFFSET(W5, ROW(W5:W99971)-ROW(W5), 0)), 0), 0))),"") -> VT-HV-TT-085
M3: =SUMPRODUCT(SUBTOTAL(109, OFFSET(M5, ROW(M5:M99999)-ROW(M5), 0)), (F5:F99999<>"") * (F5:F99999<>0)) -> 39 | N3: =SUMPRODUCT(SUBTOTAL(109, OFFSET(N5, ROW(N5:N99999)-ROW(N5), 0)), (F5:F99999<>"") * (F5:F99999<>0)) -> 193299.62 | P3: =SUMPRODUCT(SUBTOTAL(109, OFFSET(P5, ROW(P5:P99995)-ROW(P5), 0)), (E5:E99995<>"") * (E5:E99995<>0)) -> 150089.75 | Q3: =SUMPRODUCT(SUBTOTAL(109, OFFSET(Q5, ROW(Q5:Q99999)-ROW(Q5), 0)), (F5:F99999<>"") * (F5:F99999<>0)) -> 169512.9 | R3: =SUMPRODUCT(SUBTOTAL(109, OFFSET(R5, ROW(R5:R99999)-ROW(R5), 0)), (F5:F99999<>"") * (F5:F99999<>0)) -> 23786.72 | S3: =SUMPRODUCT(SUBTOTAL(109, OFFSET(S5, ROW(S5:S99999)-ROW(S5), 0)), (F5:F99999<>"") * (F5:F99999<>0)) -> 29469.6 | T3: =SUMPRODUCT(SUBTOTAL(109, OFFSET(T5, ROW(T5:T99999)-ROW(T5), 0)), (F5:F99999<>"") * (F5:F99999<>0)) -> 14184.71 | U3: =SUMPRODUCT(SUBTOTAL(109, OFFSET(U5, ROW(U5:U99999)-ROW(U5), 0)), (F5:F99999<>"") * (F5:F99999<>0)) -> 1050.61 | W3: =N3-P3-S3-T3-U3 -> -1495.05
A4: No STT | B4: Project name Dự Án | C4: NESTING NO | D4: Phase Hạng Mục | E4: Type PCS | F4: Material Mác Thép | G4: Size Quy Cách | H4: Thickness (mm) | I4: Width (mm) | J4: Length (mm) | K4: Unit ĐVT | L4: KLR (Kg/m3) | M4: Qty S.Lượng | N4: Weight (kg) | O4: Nguồn Gốc Vật Tư | P4: Khối Lượng Thành Phẩm | Q4: Lệnh Xuất Vật Tư Nguyên Khổ (kg) | R4: Lệnh Xuất Remain (kg) | S4: Lệnh Thu Remain (kg) | T4: Lệnh Thu Phế Liệu (kg) | U4: Phế Liệu Tiêu Hao (Không Thu Hồi) (kg) | V4: Lần Ban Hành | W4: =IFERROR(IF(A4="No STT","Lệnh Sản Xuất",LEFT(C4,FIND("#",SUBSTITUTE(C4,"-","#",4))-1)),"") -> Lệnh Sản Xuất | X4: =IF(C4<>"",IF('List chi tiet'!$B$2<>"",'List chi tiet'!$B$2,""),"") -> 10626-051 DG SÂN VẬN ĐỘNG HÙNG VƯƠNG
A5: 1 | B5: 10626-051 | C5: VT-HV-TT-001-CHANPINX30/Y21-Y22-Q355-SP25-001 | D5: PIN MB1 PIN2 (X30/Y21-Y22) | E5: PLATE | F5: Q355 | G5: 25x2200x12000 | H5: 25 | I5: 2200 | J5: 12000 | K5: Pcs | M5: 1 | N5: 5181 | O5: NEWPLATE | P5: 2378.55 | Q5: 5181 | S5: 2618.76 | T5: 167.04 | U5: 16.65 | V5: 1 | W5: VT-HV-TT-001 | X5: 10626-051 DG SÂN VẬN ĐỘNG HÙNG VƯƠNG | Y5: REV
A6: 2 | B6: 10626-051 | C6: VT-HV-TT-001-CHANPINX30/Y21-Y22-Q355-SP30-001 | D6: PIN MB1 PIN2 (X30/Y21-Y22) | E6: PLATE | F6: Q355 | G6: 30x2000x12000 | H6: 30 | I6: 2000 | J6: 12000 | K6: Pcs | M6: 1 | N6: 5652 | O6: NEWPLATE | P6: 5027.2 | Q6: 5652 | T6: 589.61 | U6: 35.19 | V6: 1 | W6: VT-HV-TT-001 | X6: 10626-051 DG SÂN VẬN ĐỘNG HÙNG VƯƠNG
A7: 3 | B7: 10626-051 | C7: VT-HV-TT-001-CHANPINX30/Y21-Y22-Q355-SP30-002 | D7: PIN MB1 PIN2 (X30/Y21-Y22) | E7: PLATE | F7: Q355 | G7: 30x2000x12000 | H7: 30 | I7: 2000 | J7: 12000 | K7: Pcs | M7: 1 | N7: 5652 | O7: NEWPLATE | P7: 4951.08 | Q7: 5652 | T7: 666.26 | U7: 34.66 | V7: 1 | W7: VT-HV-TT-001 | X7: 10626-051 DG SÂN VẬN ĐỘNG HÙNG VƯƠNG
A8: 4 | B8: 10626-051 | C8: VT-HV-TT-001-CHANPINX30/Y21-Y22-Q355-SP30-003 | D8: PIN MB1 PIN2 (X30/Y21-Y22) | E8: PLATE | F8: Q355 | G8: 30x2000x12000 | H8: 30 | I8: 2000 | J8: 12000 | K8: Pcs | M8: 1 | N8: 5652 | O8: NEWPLATE | P8: 366.64 | Q8: 5652 | S8: 5208.79 | T8: 74 | U8: 2.57 | V8: 1 | W8: VT-HV-TT-001 | X8: 10626-051 DG SÂN VẬN ĐỘNG HÙNG VƯƠNG
A9: 5 | B9: 10626-051 | C9: VT-HV-TT-001-CHANPINX30/Y21-Y22-Q355-SP40-001 | D9: PIN MB1 PIN2 (X30/Y21-Y22) | E9: PLATE | F9: Q355 | G9: 40x2500x12000 | H9: 40 | I9: 2500 | J9: 12000 | K9: Pcs | M9: 1 | N9: 9420 | O9: NEWPLATE | P9: 2347.27 | Q9: 9420 | S9: 6794.16 | T9: 262.14 | U9: 16.43 | V9: 1 | W9: VT-HV-TT-001 | X9: 10626-051 DG SÂN VẬN ĐỘNG HÙNG VƯƠNG
A10: 6 | B10: 10626-051 | C10: VT-HV-TT-001-CHANPINX30/Y21-Y22-Q355-SP80-001 | D10: PIN MB1 PIN2 (X30/Y21-Y22) | E10: PLATE | F10: Q355B | G10: 80x2750x12000 | H10: 80 | I10: 2750 | J10: 12000 | K10: Pcs | M10: 1 | N10: 20724 | O10: NEWPLATE | P10: 19107.21 | Q10: 20724 | T10: 1483.04 | U10: 133.75 | V10: 1 | W10: VT-HV-TT-001 | X10: 10626-051 DG SÂN VẬN ĐỘNG HÙNG VƯƠNG | Y10: REV
A11: 7 | B11: 10626-051 | C11: VT-HV-TT-001-CHANPINX30/Y21-Y22-Q355-SP80-002 | D11: PIN MB1 PIN2 (X30/Y21-Y22) | E11: PLATE | F11: Q355B | G11: 80x2750x12000 | H11: 80 | I11: 2750 | J11: 12000 | K11: Pcs | M11: 1 | N11: 20724 | O11: NEWPLATE | P11: 19135.39 | Q11: 20724 | T11: 1454.66 | U11: 133.95 | V11: 1 | W11: VT-HV-TT-001 | X11: 10626-051 DG SÂN VẬN ĐỘNG HÙNG VƯƠNG | Y11: REV
A12: 8 | B12: 10626-051 | C12: VT-HV-TT-001-CHANPINX30/Y21-Y22-Q355-SP80-003 | D12: PIN MB1 PIN2 (X30/Y21-Y22) | E12: PLATE | F12: Q355B | G12: 80x2750x12000 | H12: 80 | I12: 2750 | J12: 12000 | K12: Pcs | M12: 1 | N12: 20724 | O12: NEWPLATE | P12: 20143.29 | Q12: 20724 | T12: 439.71 | U12: 141 | V12: 1 | W12: VT-HV-TT-001 | X12: 10626-051 DG SÂN VẬN ĐỘNG HÙNG VƯƠNG | Y12: REV
A13: 9 | B13: 10626-051 | C13: VT-HV-TT-001-CHANPINX30/Y21-Y22-Q355-SP80-004 | D13: PIN MB1 PIN2 (X30/Y21-Y22) | E13: PLATE | F13: Q355B | G13: 80x2750x12000 | H13: 80 | I13: 2750 | J13: 12000 | K13: Pcs | M13: 1 | N13: 20724 | O13: NEWPLATE | P13: 20003.5 | Q13: 20724 | T13: 580.48 | U13: 140.02 | V13: 1 | W13: VT-HV-TT-001 | X13: 10626-051 DG SÂN VẬN ĐỘNG HÙNG VƯƠNG | Y13: REV
A14: 10 | B14: 10626-051 | C14: VT-HV-TT-001-CHANPINX30/Y21-Y22-Q355-SP80-005 | D14: PIN MB1 PIN2 (X30/Y21-Y22) | E14: PLATE | F14: Q355B | G14: 80x2750x12000 | H14: 80 | I14: 2750 | J14: 12000 | K14: Pcs | M14: 1 | N14: 20724 | O14: NEWPLATE | P14: 20055.83 | Q14: 20724 | T14: 527.78 | U14: 140.39 | V14: 1 | W14: VT-HV-TT-001 | X14: 10626-051 DG SÂN VẬN ĐỘNG HÙNG VƯƠNG | Y14: REV
A15: 11 | B15: 10626-051 | C15: VT-HV-TT-001-CHANPINX30/Y21-Y22-Q355-SP80-006 | D15: PIN MB1 PIN2 (X30/Y21-Y22) | E15: PLATE | F15: Q355B | G15: 80x2750x12000 | H15: 80 | I15: 2750 | J15: 12000 | K15: Pcs | M15: 1 | N15: 20724 | O15: NEWPLATE | P15: 19526.2 | Q15: 20724 | T15: 1061.12 | U15: 136.68 | V15: 1 | W15: VT-HV-TT-001 | X15: 10626-051 DG SÂN VẬN ĐỘNG HÙNG VƯƠNG | Y15: REV
A16: 12 | B16: 10626-051 | C16: VT-HV-TT-001-CHANPINX30/Y21-Y22-Q355-SP80-007 | D16: PIN MB1 PIN2 (X30/Y21-Y22) | E16: PLATE | F16: Q355B | G16: 80x2750x12000 | H16: 80 | I16: 2750 | J16: 12000 | K16: Pcs | M16: 1 | N16: 20724 | O16: NEWPLATE | P16: 3465.71 | Q16: 20724 | S16: 16994.09 | T16: 239.94 | U16: 24.26 | V16: 1 | W16: VT-HV-TT-001 | X16: 10626-051 DG SÂN VẬN ĐỘNG HÙNG VƯƠNG | Y16: REV
A17: 13 | B17: 10626-051 | C17: VT-HV-TT-001-CHANPINX30/Y21-Y22-Q355-SP120-001 | D17: PIN MB1 PIN2 (X30/Y21-Y22) | E17: PLATE | F17: Q355 | G17: 120x2300x12000 | H17: 120 | I17: 2300 | J17: 12000 | K17: Pcs | M17: 1 | N17: 25999.2 | O17: NEWPLATE | P17: 25640.81 | Q17: 25999.2 | T17: 178.9 | U17: 179.49 | V17: 1 | W17: VT-HV-TT-001 | X17: 10626-051 DG SÂN VẬN ĐỘNG HÙNG VƯƠNG
A18: 14 | B18: 10626-051 | C18: VT-HV-TT-001-CHANPINX30/Y21-Y22-Q355-SP120-002 | D18: PIN MB1 PIN2 (X30/Y21-Y22) | E18: PLATE | F18: Q355 | G18: 120x2050x12000 | H18: 120 | I18: 2050 | J18: 12000 | K18: Pcs | M18: 1 | N18: 23173.2 | O18: NEWPLATE | P18: 22322.9 | Q18: 23173.2 | T18: 694.04 | U18: 156.26 | V18: 1 | W18: VT-HV-TT-001 | X18: 10626-051 DG SÂN VẬN ĐỘNG HÙNG VƯƠNG
A19: 15 | B19: 10626-051 | C19: VT-HV-TT-001-CHANPINX30/Y21-Y22-Q355-SP120-003 | D19: PIN MB1 PIN2 (X30/Y21-Y22) | E19: PLATE | F19: Q355 | G19: 120x2300x12000 | H19: 120 | I19: 2300 | J19: 12000 | K19: Pcs | M19: 1 | N19: 25999.2 | O19: NEWPLATE | P19: 22949.31 | Q19: 25999.2 | T19: 2889.24 | U19: 160.65 | V19: 1 | W19: VT-HV-TT-001 | X19: 10626-051 DG SÂN VẬN ĐỘNG HÙNG VƯƠNG
A20: 16 | B20: 10626-051 | C20: VT-HV-TT-001-CHANPINX30/Y21-Y22-Q355-SP120-004 | D20: PIN MB1 PIN2 (X30/Y21-Y22) | E20: PLATE | F20: Q355 | G20: 120x2500x12000 | H20: 120 | I20: 2500 | J20: 12000 | K20: Pcs | M20: 1 | N20: 28260 | O20: NEWPLATE | P20: 26806.06 | Q20: 28260 | T20: 1266.3 | U20: 187.64 | V20: 1 | W20: VT-HV-TT-001 | X20: 10626-051 DG SÂN VẬN ĐỘNG HÙNG VƯƠNG
A21: 17 | B21: 10626-051 | C21: VT-HV-TT-001-CHANPINX30/Y21-Y22-Q355-SP120-005 | D21: PIN MB1 PIN2 (X30/Y21-Y22) | E21: PLATE | F21: Q355 | G21: 120x2500x12000 | H21: 120 | I21: 2500 | J21: 12000 | K21: Pcs | M21: 1 | N21: 28260 | O21: NEWPLATE | P21: 27429.66 | Q21: 28260 | T21: 638.33 | U21: 192.01 | V21: 1 | W21: VT-HV-TT-001 | X21: 10626-051 DG SÂN VẬN ĐỘNG HÙNG VƯƠNG
A22: 18 | B22: 10626-051 | C22: VT-HV-TT-001-CHANPINX30/Y21-Y22-Q355-SP120-006 | D22: PIN MB1 PIN2 (X30/Y21-Y22) | E22: PLATE | F22: Q355 | G22: 120x2300x12000 | H22: 120 | I22: 2300 | J22: 12000 | K22: Pcs | M22: 1 | N22: 25999.2 | O22: NEWPLATE | P22: 25647.42 | Q22: 25999.2 | T22: 172.25 | U22: 179.53 | V22: 1 | W22: VT-HV-TT-001 | X22: 10626-051 DG SÂN VẬN ĐỘNG HÙNG VƯƠNG
A23: 19 | B23: 10626-051 | C23: VT-HV-TT-001-CHANPINX30/Y21-Y22-Q355-SP120-007 | D23: PIN MB1 PIN2 (X30/Y21-Y22) | E23: PLATE | F23: Q355 | G23: 120x2500x12000 | H23: 120 | I23: 2500 | J23: 12000 | K23: Pcs | M23: 1 | N23: 28260 | O23: NEWPLATE | P23: 26710.66 | Q23: 28260 | T23: 1362.37 | U23: 186.97 | V23: 1 | W23: VT-HV-TT-001 | X23: 10626-051 DG SÂN VẬN ĐỘNG HÙNG VƯƠNG
A24: 20 | B24: 10626-051 | C24: VT-HV-TT-001-CHANPINX30/Y21-Y22-Q355-SP120-008 | D24: PIN MB1 PIN2 (X30/Y21-Y22) | E24: PLATE | F24: Q355 | G24: 120x2500x13000 | H24: 120 | I24: 2500 | J24: 13000 | K24: Pcs | M24: 1 | N24: 30615 | O24: NEWPLATE | P24: 29105.11 | Q24: 30615 | T24: 1306.15 | U24: 203.74 | V24: 1 | W24: VT-HV-TT-001 | X24: 10626-051 DG SÂN VẬN ĐỘNG HÙNG VƯƠNG
A25: 21 | B25: 10626-051 | C25: VT-HV-TT-001-CHANPINX30/Y21-Y22-Q355-SP120-009 | D25: PIN MB1 PIN2 (X30/Y21-Y22) | E25: PLATE | F25: Q355 | G25: 120x2500x13000 | H25: 120 | I25: 2500 | J25: 13000 | K25: Pcs | M25: 1 | N25: 30615 | O25: NEWPLATE | P25: 29594.29 | Q25: 30615 | T25: 813.55 | U25: 207.16 | V25: 1 | W25: VT-HV-TT-001 | X25: 10626-051 DG SÂN VẬN ĐỘNG HÙNG VƯƠNG
A26: 22 | B26: 10626-051 | C26: VT-HV-TT-001-CHANPINX30/Y21-Y22-Q355-SP120-010 | D26: PIN MB1 PIN2 (X30/Y21-Y22) | E26: PLATE | F26: Q355 | G26: 120x2500x12000 | H26: 120 | I26: 2500 | J26: 12000 | K26: Pcs | M26: 1 | N26: 28260 | O26: NEWPLATE | P26: 26687.61 | Q26: 28260 | T26: 1385.58 | U26: 186.81 | V26: 1 | W26: VT-HV-TT-001 | X26: 10626-051 DG SÂN VẬN ĐỘNG HÙNG VƯƠNG
A27: 23 | B27: 10626-051 | C27: VT-HV-TT-001-CHANPINX30/Y21-Y22-Q355-SP120-011 | D27: PIN MB1 PIN2 (X30/Y21-Y22) | E27: PLATE | F27: Q355 | G27: 120x2500x12000 | H27: 120 | I27: 2500 | J27: 12000 | K27: Pcs | M27: 1 | N27: 28260 | O27: NEWPLATE | P27: 26011.6 | Q27: 28260 | T27: 2066.32 | U27: 182.08 | V27: 1 | W27: VT-HV-TT-001 | X27: 10626-051 DG SÂN VẬN ĐỘNG HÙNG VƯƠNG
A28: 24 | B28: 10626-051 | C28: VT-HV-TT-001-CHANPINX30/Y21-Y22-Q355-SP120-012 | D28: PIN MB1 PIN2 (X30/Y21-Y22) | E28: PLATE | F28: Q355 | G28: 120x2300x12000 | H28: 120 | I28: 2300 | J28: 12000 | K28: Pcs | M28: 1 | N28: 25999.2 | O28: NEWPLATE | P28: 12130.8 | Q28: 25999.2 | S28: 12101.52 | T28: 1681.96 | U28: 84.92 | V28: 1 | W28: VT-HV-TT-001 | X28: 10626-051 DG SÂN VẬN ĐỘNG HÙNG VƯƠNG
A29: 25 | B29: 10626-051 | C29: VT-HV-TT-001-CHANPINX30/Y21-Y22-Q355-SP120-013 | D29: PIN MB1 PIN2 (X30/Y21-Y22) | E29: PLATE | F29: Q355 | G29: 120x2300x12000 | H29: 120 | I29: 2300 | J29: 12000 | K29: Pcs | M29: 1 | N29: 25999.2 | O29: NEWPLATE | P29: 24581.87 | Q29: 25999.2 | T29: 1245.26 | U29: 172.07 | V29: 1 | W29: VT-HV-TT-001 | X29: 10626-051 DG SÂN VẬN ĐỘNG HÙNG VƯƠNG
A30: 26 | B30: 10626-051 | C30: VT-HV-TT-001-CHANPINX30/Y21-Y22-Q355-SP120-014 | D30: PIN MB1 PIN2 (X30/Y21-Y22) | E30: PLATE | F30: Q355 | G30: 120x2500x13000 | H30: 120 | I30: 2500 | J30: 13000 | K30: Pcs | M30: 1 | N30: 30615 | O30: NEWPLATE | P30: 28060.74 | Q30: 30615 | T30: 2357.83 | U30: 196.43 | V30: 1 | W30: VT-HV-TT-001 | X30: 10626-051 DG SÂN VẬN ĐỘNG HÙNG VƯƠNG
A31: 27 | B31: 10626-051 | C31: VT-HV-TT-001-CHANPINX30/Y21-Y22-Q355-SP120-015 | D31: PIN MB1 PIN2 (X30/Y21-Y22) | E31: PLATE | F31: Q355 | G31: 120x2500x12000 | H31: 120 | I31: 2500 | J31: 12000 | K31: Pcs | M31: 1 | N31: 28260 | O31: NEWPLATE | P31: 26605.07 | Q31: 28260 | T31: 1468.69 | U31: 186.24 | V31: 1 | W31: VT-HV-TT-001 | X31: 10626-051 DG SÂN VẬN ĐỘNG HÙNG VƯƠNG
A32: 28 | B32: 10626-051 | C32: VT-HV-TT-001-CHANPINX30/Y21-Y22-Q355-SP120-016 | D32: PIN MB1 PIN2 (X30/Y21-Y22) | E32: PLATE | F32: Q355 | G32: 120x2500x12000 | H32: 120 | I32: 2500 | J32: 12000 | K32: Pcs | M32: 1 | N32: 28260 | O32: NEWPLATE | P32: 26950.45 | Q32: 28260 | T32: 1120.9 | U32: 188.65 | V32: 1 | W32: VT-HV-TT-001 | X32: 10626-051 DG SÂN VẬN ĐỘNG HÙNG VƯƠNG
A33: 29 | B33: 10626-051 | C33: VT-HV-TT-001-CHANPINX30/Y21-Y22-Q355-SP120-017 | D33: PIN MB1 PIN2 (X30/Y21-Y22) | E33: PLATE | F33: Q355 | G33: 120x2500x12000 | H33: 120 | I33: 2500 | J33: 12000 | K33: Pcs | M33: 1 | N33: 28260 | O33: NEWPLATE | P33: 21513.18 | Q33: 28260 | S33: 6395.83 | T33: 200.4 | U33: 150.59 | V33: 1 | W33: VT-HV-TT-001 | X33: 10626-051 DG SÂN VẬN ĐỘNG HÙNG VƯƠNG
A34: 30 | B34: 10626-051 | C34: VT-HV-TT-001-CHANPINX30/Y21-Y22-Q355-SP120-018 | D34: PIN MB1 PIN2 (X30/Y21-Y22) | E34: PLATE | F34: Q355 | G34: 120x2500x12000 | H34: 120 | I34: 2500 | J34: 12000 | K34: Pcs | M34: 1 | N34: 28260 | O34: NEWPLATE | P34: 24165.69 | Q34: 28260 | S34: 2907.62 | T34: 1017.53 | U34: 169.16 | V34: 1 | W34: VT-HV-TT-001 | X34: 10626-051 DG SÂN VẬN ĐỘNG HÙNG VƯƠNG
A35: 31 | B35: 10626-051 | C35: VT-HV-TT-001-CHANPINX30/Y21-Y22-Q355-SP120-019 | D35: PIN MB1 PIN2 (X30/Y21-Y22) | E35: PLATE | F35: Q355 | G35: 120x2300x12000 | H35: 120 | I35: 2300 | J35: 12000 | K35: Pcs | M35: 1 | N35: 25999.2 | O35: NEWPLATE | P35: 22095.31 | Q35: 25999.2 | S35: 2907.62 | T35: 841.6 | U35: 154.67 | V35: 1 | W35: VT-HV-TT-001 | X35: 10626-051 DG SÂN VẬN ĐỘNG HÙNG VƯƠNG
A36: 32 | B36: 10626-051 | C36: VT-HV-TT-001-CHANPINX30/Y21-Y22-Q355-SP120-020 | D36: PIN MB1 PIN2 (X30/Y21-Y22) | E36: PLATE | F36: Q355 | G36: 120x2300x12000 | H36: 120 | I36: 2300 | J36: 12000 | K36: Pcs | M36: 1 | N36: 25999.2 | O36: NEWPLATE | P36: 16595.59 | Q36: 25999.2 | S36: 7897.8 | T36: 1389.64 | U36: 116.17 | V36: 1 | W36: VT-HV-TT-001 | X36: 10626-051 DG SÂN VẬN ĐỘNG HÙNG VƯƠNG
A37: 33 | B37: 10626-051 | C37: VT-HV-TT-001-CHANPINX30/Y21-Y22-Q355-SP120-021 | D37: PIN MB1 PIN2 (X30/Y21-Y22) | E37: PLATE | F37: Q355 | G37: 120x2300x12000 | H37: 120 | I37: 2300 | J37: 12000 | K37: Pcs | M37: 1 | N37: 25999.2 | O37: NEWPLATE | P37: 16595.59 | Q37: 25999.2 | S37: 7897.8 | T37: 1389.64 | U37: 116.17 | V37: 1 | W37: VT-HV-TT-001 | X37: 10626-051 DG SÂN VẬN ĐỘNG HÙNG VƯƠNG
A38: 34 | B38: 10626-051 | C38: VT-HV-TT-001-CHANPINX30/Y21-Y22-Q355-SP120-022 | D38: PIN MB1 PIN2 (X30/Y21-Y22) | E38: PLATE | F38: Q355 | G38: 120x2300x12000 | H38: 120 | I38: 2300 | J38: 12000 | K38: Pcs | M38: 1 | N38: 25999.2 | O38: NEWPLATE | P38: 17607.03 | Q38: 25999.2 | S38: 7107.94 | T38: 1160.98 | U38: 123.25 | V38: 1 | W38: VT-HV-TT-001 | X38: 10626-051 DG SÂN VẬN ĐỘNG HÙNG VƯƠNG
A39: 1 | B39: 10626-051 | C39: VT-HV-TT-002-PINX01_Y21-Y22-Q355-SP25-001 | D39: CHÂN PIN MB1 PIN2 (X01/Y21-Y22)-REV04 | E39: PLATE | F39: Q355 | G39: 25x1112x12000 | H39: 25 | I39: 1112 | J39: 12000 | K39: Pcs | M39: 1 | N39: 2618.76 | O39: VT-HV-TT-001-CHANPINX30/Y21-Y22-Q355-SP25-001 | P39: 2378.55 | R39: 2618.76 | T39: 223.56 | U39: 16.65 | V39: 2 | W39: VT-HV-TT-002 | X39: 10626-051 DG SÂN VẬN ĐỘNG HÙNG VƯƠNG
A40: 2 | B40: 10626-051 | C40: VT-HV-TT-002-PINX01_Y21-Y22-Q355-SP30-001 | D40: CHÂN PIN MB1 PIN2 (X01/Y21-Y22)-REV04 | E40: PLATE | F40: Q355 | G40: 30x2000x11059 | H40: 30 | I40: 2000 | J40: 11059 | K40: Pcs | M40: 1 | N40: 5208.79 | O40: VT-HV-TT-001-CHANPINX30/Y21-Y22-Q355-SP30-003 | P40: 4573.85 | R40: 5208.79 | T40: 602.92 | U40: 32.02 | V40: 2 | W40: VT-HV-TT-002 | X40: 10626-051 DG SÂN VẬN ĐỘNG HÙNG VƯƠNG
...

Sheet Hao hut vat tu
A1: Thông Tin Dự Án | C1: =IF(LEN('List chi tiet'!$B$3)=0,"",'List chi tiet'!$B$3) -> 10626-051 | I1: Số Liệu Trung Bình Cho Dự Án | K1: =IF(LEN('List chi tiet'!$B$3)=0,"",'List chi tiet'!$B$3) -> 10626-051 | L1: ĐVT | O1: =IFERROR(IF(C1="Total",#REF!,IF(C1<>"Total",MID(C1, FIND("@", SUBSTITUTE(C1, "-", "@", 4)) + 1, FIND("@", SUBSTITUTE(C1, "-", "@", LEN(C1) - LEN(SUBSTITUTE(C1, "-", "")))) - FIND("@", SUBSTITUTE(C1, "-", "@", 4)) - 1))),"")
A2: Project: | I2: Tổng Thành Phẩm (Total Nesting) : | K2: =SUBTOTAL(109, F13:F99999) -> 150089.75 | L2: kg
A3: Phase: | C3: =IFERROR(INDEX(O13:O99929, MATCH(1, INDEX(SUBTOTAL(3, OFFSET(O13, ROW(O13:O99929)-ROW(O13), 0)), 0), 0)),"") -> GIAN NANG 3A-UT1 | I3: Tổng Tấm Mới Cấp Vào (New Plate) : | K3: =SUBTOTAL(109, D13:D99999) -> 169512.9 | L3: kg
A4: OMS: | I4: Tổng Remain Cấp Vào (Remain In) : | K4: =SUBTOTAL(109, E13:E99999) -> 23786.72 | L4: kg
A5: Nesting: | I5: Tổng Remain Sinh Ra (Remain Out): | K5: =SUBTOTAL(109, G13:G99999) -> 29469.6 | L5: kg
A6: LSX | C6: =IFERROR(INDEX(M13:M99929, MATCH(1, INDEX(SUBTOTAL(3, OFFSET(M13, ROW(M13:M99929)-ROW(M13), 0)), 0), 0)),"") -> VT-HV-TT-085 | I6: % Remain: | K6: =IF(K2=0,0,K5/K2) -> 0.19634652 | L6: %
A7: Rev: | B7: 0 | I7: Tổng tiêu hao: | K7: =SUBTOTAL(109, I13:I99999) -> 1050.61 | L7: kg
A8: Date: | I8: Tổng Phế Liệu (Waste) : | K8: =SUBTOTAL(109, J13:J99999) -> 14184.71 | L8: kg
I9: % Phế Liệu (% Waste) : | K9: =IF(K2=0,0,K8/K2) -> 0.094508186 | L9: %
I10: Hao Hụt: | K10: =IF(K2=0,0,(K7+K8)/K2) -> 0.10150806 | L10: % | O10: =IFERROR(IF(C10="Total",O9,IF(C10<>"Total",MID(C10, FIND("@", SUBSTITUTE(C10, "-", "@", 4)) + 1, FIND("@", SUBSTITUTE(C10, "-", "@", LEN(C10) - LEN(SUBSTITUTE(C10, "-", "")))) - FIND("@", SUBSTITUTE(C10, "-", "@", 4)) - 1))),"")
A11: I. Số Liệu Chi Tiết Thép Tấm (Plate) | D11: =IF(C11<>"",SUBTOTAL(9,D10:D10),"") | E11: =IF(C11<>"",SUBTOTAL(9,E10:E10),"") | F11: =IF(C11<>"",SUBTOTAL(9,F10:F10),"") | G11: =IF(C11<>"",SUBTOTAL(9,G10:G10),"") | H11: =IF(C11<>"",IF(D11+E11>0, G11/(D11+E11), 0),"") | I11: =IF(C11<>"",SUBTOTAL(9,I10:I10),"") | J11: =IF(C11<>"",SUBTOTAL(9,J10:J10),"") | K11: =IF(C11<>"",IF(D11+E11>0, J11/(D11+E11), 0),"") | L11: =IF(C11<>"",IF(F11>0, J11/F11, 0),"") | M11: =IFERROR(IF(C11="Nesting No","LSX",IF(C11="Total",M10,TRIM(LEFT(C11,FIND("#",SUBSTITUTE(C11,"-","#",4))-1)))),"") | N11: =IFERROR(IF(C11="Nesting No","Lần B.Hành",VALUE(IF(C11="Total",N10,TRIM(RIGHT(SUBSTITUTE(M11,"-",REPT(" ",99)),99))))),"") | O11: =IFERROR(IF(C11="Nesting No","Hạng Mục",IF(C11="Total",O10,TRIM(MID(SUBSTITUTE(C11,"-",REPT(" ",LEN(C11))),4*LEN(C11)+1,LEN(C11))))),"")
A12: STT | B12: DÀY | C12: Nesting No | D12: Tấm mới (New Plate) | E12: Remain Sử Dụng(In) | F12: Thành Phẩm | G12: Remain Sinh Ra(Out) | H12: =IFERROR(IF(C12="Nesting No","%Remain",IF(D12+E12>0, G12/(D12+E12),"")),"") -> %Remain | I12: =IFERROR(IF(C12<>"",IF(C12="Nesting No","Tiêu Hao (kg)",ROUND(F12*0.1/100, 2)),""),"") -> Tiêu Hao (kg) | J12: =IFERROR(IF(C12<>"",IF(C12="Nesting No","Phế Liệu(Waste)",MAX(ROUND(D12+E12-F12-G12-I12, 2), 0)),""),"") -> Phế Liệu(Waste) | K12: =IFERROR(IF(C12="Nesting No","%Phế Liệu",IF(D12+E12>0, J12/(D12+E12),"")),"") -> %Phế Liệu | L12: =IFERROR(IF(C12="Nesting No","%Hao Hụt",IF(F12>0, J12/F12,"")),"") -> %Hao Hụt | M12: =IFERROR(IF(C12="Nesting No","LSX",IF(C12="Total",M11,TRIM(LEFT(C12,FIND("#",SUBSTITUTE(C12,"-","#",4))-1)))),"") -> LSX | N12: =IFERROR(IF(C12="Nesting No","Lần B.Hành",VALUE(IF(C12="Total",N11,TRIM(RIGHT(SUBSTITUTE(M12,"-",REPT(" ",99)),99))))),"") -> Lần B.Hành | O12: =IFERROR(IF(C12="Nesting No","Hạng Mục",IF(C12="Total",O11,TRIM(MID(SUBSTITUTE(C12,"-",REPT(" ",LEN(C12))),4*LEN(C12)+1,LEN(C12))))),"") -> Hạng Mục
A13: 1 | B13: PL25 | C13: VT-HV-TT-001-CHANPINX30/Y21-Y22-Q355-SP25-001 | D13: 5181 | E13: 0 | F13: 2378.55 | G13: 2618.76 | H13: 0.50545455 | I13: 16.65 | J13: 167.04 | K13: 0.03224088 | L13: 0.07022766 | M13: VT-HV-TT-001 | N13: 1 | O13: PIN MB1 PIN2 (X30/Y21-Y22)
A14: 2 | B14: PL30 | C14: VT-HV-TT-001-CHANPINX30/Y21-Y22-Q355-SP30-001 | D14: 5652 | E14: 0 | F14: 5027.2 | G14: 0 | H14: 0 | I14: 35.19 | J14: 589.61 | K14: 0.10431883 | L14: 0.11728398 | M14: VT-HV-TT-001 | N14: 1 | O14: PIN MB1 PIN2 (X30/Y21-Y22)
A15: 3 | B15: PL30 | C15: VT-HV-TT-001-CHANPINX30/Y21-Y22-Q355-SP30-002 | D15: 5652 | E15: 0 | F15: 4951.08 | G15: 0 | H15: 0 | I15: 34.66 | J15: 666.26 | K15: 0.1178804 | L15: 0.13456862 | M15: VT-HV-TT-001 | N15: 1 | O15: PIN MB1 PIN2 (X30/Y21-Y22)
A16: 4 | B16: PL30 | C16: VT-HV-TT-001-CHANPINX30/Y21-Y22-Q355-SP30-003 | D16: 5652 | E16: 0 | F16: 366.64 | G16: 5208.79 | H16: 0.92158351 | I16: 2.57 | J16: 74 | K16: 0.013092711 | L16: 0.20183286 | M16: VT-HV-TT-001 | N16: 1 | O16: PIN MB1 PIN2 (X30/Y21-Y22)
A17: 5 | B17: PL40 | C17: VT-HV-TT-001-CHANPINX30/Y21-Y22-Q355-SP40-001 | D17: 9420 | E17: 0 | F17: 2347.27 | G17: 6794.16 | H17: 0.72124841 | I17: 16.43 | J17: 262.14 | K17: 0.027828025 | L17: 0.11167867 | M17: VT-HV-TT-001 | N17: 1 | O17: PIN MB1 PIN2 (X30/Y21-Y22)
A18: 6 | B18: PL80 | C18: VT-HV-TT-001-CHANPINX30/Y21-Y22-Q355-SP80-001 | D18: 20724 | E18: 0 | F18: 19107.21 | G18: 0 | H18: 0 | I18: 133.75 | J18: 1483.04 | K18: 0.071561475 | L18: 0.077616774 | M18: VT-HV-TT-001 | N18: 1 | O18: PIN MB1 PIN2 (X30/Y21-Y22)
A19: 7 | B19: PL80 | C19: VT-HV-TT-001-CHANPINX30/Y21-Y22-Q355-SP80-002 | D19: 20724 | E19: 0 | F19: 19135.39 | G19: 0 | H19: 0 | I19: 133.95 | J19: 1454.66 | K19: 0.070192048 | L19: 0.076019355 | M19: VT-HV-TT-001 | N19: 1 | O19: PIN MB1 PIN2 (X30/Y21-Y22)
A20: 8 | B20: PL80 | C20: VT-HV-TT-001-CHANPINX30/Y21-Y22-Q355-SP80-003 | D20: 20724 | E20: 0 | F20: 20143.29 | G20: 0 | H20: 0 | I20: 141 | J20: 439.71 | K20: 0.021217429 | L20: 0.021829105 | M20: VT-HV-TT-001 | N20: 1 | O20: PIN MB1 PIN2 (X30/Y21-Y22)
A21: 9 | B21: PL80 | C21: VT-HV-TT-001-CHANPINX30/Y21-Y22-Q355-SP80-004 | D21: 20724 | E21: 0 | F21: 20003.5 | G21: 0 | H21: 0 | I21: 140.02 | J21: 580.48 | K21: 0.028010037 | L21: 0.029018922 | M21: VT-HV-TT-001 | N21: 1 | O21: PIN MB1 PIN2 (X30/Y21-Y22)
A22: 10 | B22: PL80 | C22: VT-HV-TT-001-CHANPINX30/Y21-Y22-Q355-SP80-005 | D22: 20724 | E22: 0 | F22: 20055.83 | G22: 0 | H22: 0 | I22: 140.39 | J22: 527.78 | K22: 0.025467091 | L22: 0.02631554 | M22: VT-HV-TT-001 | N22: 1 | O22: PIN MB1 PIN2 (X30/Y21-Y22)
A23: 11 | B23: PL80 | C23: VT-HV-TT-001-CHANPINX30/Y21-Y22-Q355-SP80-006 | D23: 20724 | E23: 0 | F23: 19526.2 | G23: 0 | H23: 0 | I23: 136.68 | J23: 1061.12 | K23: 0.051202471 | L23: 0.054343395 | M23: VT-HV-TT-001 | N23: 1 | O23: PIN MB1 PIN2 (X30/Y21-Y22)
A24: 12 | B24: PL80 | C24: VT-HV-TT-001-CHANPINX30/Y21-Y22-Q355-SP80-007 | D24: 20724 | E24: 0 | F24: 3465.71 | G24: 16994.09 | H24: 0.82001978 | I24: 24.26 | J24: 239.94 | K24: 0.011577881 | L24: 0.069232567 | M24: VT-HV-TT-001 | N24: 1 | O24: PIN MB1 PIN2 (X30/Y21-Y22)
... A46: 34 | B46: PL120 | C46: VT-HV-TT-001-CHANPINX30/Y21-Y22-Q355-SP120-022 | D46: 25999.2 | E46: 0 | F46: 17607.03 | G46: 7107.94 | H46: 0.27339072 | I46: 123.25 | J46: 1160.98 | K46: 0.044654451 | L46: 0.065938435 | M46: VT-HV-TT-001 | N46: 1 | O46: PIN MB1 PIN2 (X30/Y21-Y22)
A47: 1 | B47: PL25 | C47: VT-HV-TT-002-PINX01_Y21-Y22-Q355-SP25-001 | D47: 0 | E47: 2618.76 | F47: 2378.55 | G47: 0 | H47: 0 | I47: 16.65 | J47: 223.56 | K47: 0.085368648 | L47: 0.093990036 | M47: VT-HV-TT-002 | N47: 2 | O47: CHÂN PIN MB1 PIN2 (X01/Y21-Y22)-REV04 | P47: 314.02
A48: 2 | B48: PL30 | C48: VT-HV-TT-002-PINX01_Y21-Y22-Q355-SP30-001 | D48: 0 | E48: 5208.79 | F48: 4573.85 | G48: 0 | H48: 0 | I48: 32.02 | J48: 602.92 | K48: 0.11575049 | L48: 0.13181893 | M48: VT-HV-TT-002 | N48: 2 | O48: CHÂN PIN MB1 PIN2 (X01/Y21-Y22)-REV04 | P48: 511.18
A49: 3 | B49: PL30 | C49: VT-HV-TT-002-PINX01_Y21-Y22-Q355-SP30-002 | D49: 5652 | E49: 0 | F49: 1330.27 | G49: 4093.44 | H49: 0.72424628 | I49: 9.31 | J49: 218.98 | K49: 0.038743808 | L49: 0.1646132 | M49: VT-HV-TT-002 | N49: 2 | O49: CHÂN PIN MB1 PIN2 (X01/Y21-Y22)-REV04 | P49: 140.5
A50: 4 | B50: PL40 | C50: VT-HV-TT-002-PINX01_Y21-Y22-Q355B-SP40-001 | D50: 0 | E50: 6794.16 | F50: 961 | G50: 5206.04 | H50: 0.76625219 | I50: 6.73 | J50: 620.39 | K50: 0.091312245 | L50: 0.64556712 | M50: VT-HV-TT-002 | N50: 2 | O50: CHÂN PIN MB1 PIN2 (X01/Y21-Y22)-REV04 | P50: 97.07
A51: 5 | B51: PL80 | C51: VT-HV-TT-002-PINX01_Y21-Y22-Q355-SP80-001 | D51: 0 | E51: 16994.09 | F51: 15884.98 | G51: 0 | H51: 0 | I51: 111.19 | J51: 997.92 | K51: 0.058721591 | L51: 0.062821609 | M51: VT-HV-TT-002 | N51: 2 | O51: CHÂN PIN MB1 PIN2 (X01/Y21-Y22)-REV04 | P51: 106.45
A52: 6 | B52: PL80 | C52: VT-HV-TT-002-PINX01_Y21-Y22-Q355-SP80-002 | D52: 20724 | E52: 0 | F52: 19453.28 | G52: 0 | H52: 0 | I52: 136.17 | J52: 1134.55 | K52: 0.054745705 | L52: 0.058321784 | M52: VT-HV-TT-002 | N52: 2 | O52: CHÂN PIN MB1 PIN2 (X01/Y21-Y22)-REV04 | P52: 139.82
A53: 7 | B53: PL80 | C53: VT-HV-TT-002-PINX01_Y21-Y22-Q355-SP80-003 | D53: 20724 | E53: 0 | F53: 19983.68 | G53: 0 | H53: 0 | I53: 139.89 | J53: 600.43 | K53: 0.028972689 | L53: 0.030046018 | M53: VT-HV-TT-002 | N53: 2 | O53: CHÂN PIN MB1 PIN2 (X01/Y21-Y22)-REV04 | P53: 107.38
A54: 8 | B54: PL80 | C54: VT-HV-TT-002-PINX01_Y21-Y22-Q355-SP80-004 | D54: 20724 | E54: 0 | F54: 19973.11 | G54: 0 | H54: 0 | I54: 139.81 | J54: 611.08 | K54: 0.029486586 | L54: 0.030595135 | M54: VT-HV-TT-002 | N54: 2 | O54: CHÂN PIN MB1 PIN2 (X01/Y21-Y22)-REV04 | P54: 120.91
A55: 9 | B55: PL80 | C55: VT-HV-TT-002-PINX01_Y21-Y22-Q355-SP80-005 | D55: 18840 | E55: 0 | F55: 17800.1 | G55: 0 | H55: 0 | I55: 124.6 | J55: 915.3 | K55: 0.048582803 | L55: 0.051421059 | M55: VT-HV-TT-002 | N55: 2 | O55: CHÂN PIN MB1 PIN2 (X01/Y21-Y22)-REV04 | P55: 122.2
A56: 10 | B56: PL80 | C56: VT-HV-TT-002-PINX01_Y21-Y22-Q355-SP80-006 | D56: 18840 | E56: 0 | F56: 17919.38 | G56: 0 | H56: 0 | I56: 125.44 | J56: 795.18 | K56: 0.042207006 | L56: 0.044375419 | M56: VT-HV-TT-002 | N56: 2 | O56: CHÂN PIN MB1 PIN2 (X01/Y21-Y22)-REV04 | P56: 107.61
A57: 11 | B57: PL80 | C57: VT-HV-TT-002-PINX01_Y21-Y22-Q355-SP80-007 | D57: 20724 | E57: 0 | F57: 7060.77 | G57: 13014.67 | H57: 0.6279999 | I57: 49.43 | J57: 599.13 | K57: 0.028909959 | L57: 0.084853352 | M57: VT-HV-TT-002 | N57: 2 | O57: CHÂN PIN MB1 PIN2 (X01/Y21-Y22)-REV04 | P57: 63.5
A58: 12 | B58: PL80 | C58: VT-HV-TT-002-PINX01_Y21-Y22-Q355-SP80-008 | D58: 18840 | E58: 0 | F58: 3361.86 | G58: 15166.92 | H58: 0.80503822 | I58: 23.53 | J58: 287.69 | K58: 0.01527017 | L58: 0.085574652 | M58: VT-HV-TT-002 | N58: 2 | O58: CHÂN PIN MB1 PIN2 (X01/Y21-Y22)-REV04 | P58: 37.06
... A91: 45 | B91: PL120 | C91: VT-HV-TT-002-PINX01_Y21-Y22-Q355-SP120-033 | D91: 25999.2 | E91: 0 | F91: 16595.59 | G91: 7978.18 | H91: 0.30686252 | I91: 116.17 | J91: 1309.26 | K91: 0.050357703 | L91: 0.078892043 | M91: VT-HV-TT-002 | N91: 2 | O91: CHÂN PIN MB1 PIN2 (X01/Y21-Y22)-REV04 | P91: 33.01
A92: 46 | B92: PL120 | C92: VT-HV-TT-002-PINX01_Y21-Y22-Q355-SP120-034 | D92: 26423.1 | E92: 0 | F92: 18264.78 | G92: 3260.07 | H92: 0.12337954 | I92: 127.85 | J92: 4770.4 | K92: 0.180539 | L92: 0.26118026 | M92: VT-HV-TT-002 | N92: 2 | O92: CHÂN PIN MB1 PIN2 (X01/Y21-Y22)-REV04 | P92: 40.35 | Q92: REV04
A93: 47 | B93: PL120 | C93: VT-HV-TT-002-PINX01_Y21-Y22-Q355-SP120-035 | D93: 28260 | E93: 0 | F93: 26779.73 | G93: 0 | H93: 0 | I93: 187.46 | J93: 1292.81 | K93: 0.045746992 | L93: 0.048275692 | M93: VT-HV-TT-002 | N93: 2 | O93: CHÂN PIN MB1 PIN2 (X01/Y21-Y22)-REV04 | P93: 110.41
...

Sheet LSX-VT
M2: LỆNH SẢN XUẤT/ PRODUCTION ORDER
A3: CÔNG TRÌNH/ CONSTRUCTION: | C3: ='List chi tiet'!B3&"-"&'List chi tiet'!B2 -> 10626-051-10626-051 DG SÂN VẬN ĐỘNG HÙNG VƯƠNG
A4: LSX/ PRODUCTION ORDER : | C4: =INDEX(M11:M99987, MATCH(1, INDEX(SUBTOTAL(3, OFFSET(M11, ROW(M11:M99987)-ROW(M11), 0)), 0), 0)) -> VT-HV-TT-085
A5: Hạng mục/ Items: | C5: =INDEX(P11:P99987, MATCH(1, INDEX(SUBTOTAL(3, OFFSET(P11, ROW(P11:P99987)-ROW(P11), 0)), 0), 0)) -> GIAN NANG 3A-UT1
A6: Đơn vị gia công/ Processing unit: | C6: SC-VT1
A7: Lệnh xuất:
A8: Lệnh thu lỡ cỡ: | H8: =SUMPRODUCT(SUBTOTAL(109, OFFSET(H11, ROW(H11:H99999)-ROW(H11), 0)), (B11:B99999<>"") * (B11:B99999<>0)) -> 1306 | I8: =SUMPRODUCT(SUBTOTAL(109, OFFSET(I11, ROW(I11:I99999)-ROW(I11), 0)), (B11:B99999<>"") * (B11:B99999<>0)) -> 150089.75 | P8: =VALUE(SUMPRODUCT(SUBTOTAL(103,OFFSET(B11,ROW(B11:B99692)-MIN(ROW(B11:B99692)),,1)),--(B11:B99692<>""))) -> 436
A9: Lệnh Thu phế liệu: | AC9: =IFERROR(VLOOKUP(A9,'List chi tiet'!$A:$L,12,0),"")
A10: STT/ No. | B10: Tên/ mã số Name/code | C10: Dày/ Thickness | D10: Rộng/ Width | E10: Dài/ Length | F10: Mác thép/ Steel mark | G10: ĐVT/ Unit | H10: SL / Qty | I10: Khối lượng/ Weight (kg) | J10: ĐV CẮT | K10: Đơn Vị Gia Công | L10: Đơn Vị Nhận | M10: LSX | N10: Lưu ý | O10: Có Lỗ | P10: Hạng Mục | Q10: Cánh Bụng bản mã | R10: Nguyên Khổ | S10: Lỡ Cỡ | T10: Tận Dụng | U10: Chấn Bend | V10: Vát Mép | W10: Lần Ban Hành | X10: Ngày B.hành | Y10: Note | Z10: REV01 | AA10: REV02 | AB10: Mã Dự Án | AC10: NESTING | AD10: Nguồn Gốc Vật Tư | AE10: =IF(LEN('List chi tiet'!$B$2)=0,"",'List chi tiet'!$B$2) -> 10626-051 DG SÂN VẬN ĐỘNG HÙNG VƯƠNG
C11: Thép tấm lỡ cỡ cường độ Cao | D11: 6 | E11: 14.54 | F11: KG | L11: VT-HV-TT-074 | M11: 10626-051 DG SÂN VẬN ĐỘNG HÙNG VƯƠNG | N11: 29/09/2026 | O11: NGUYEN SONG HUONG | P11: REV0 | R11: Q355B | S11: 0.06 | T11: 0.8 | U11: 5.2 | V11: 6x206x1500 | AB11: =IF('List chi tiet'!V6<>"",'List chi tiet'!V6,"") -> 10626-051 | AC11: =IF('List chi tiet'!L6<>"",'List chi tiet'!L6,"") -> VT-HV-TT-001-CHANPINX30/Y21-Y22-Q355-SP25-001 | AD11: =IF('List chi tiet'!K6<>"",'List chi tiet'!K6,"") -> PL25x2200x12000
C12: Thép tấm lỡ cỡ cường độ Cao | D12: 6 | E12: -5.2 | F12: KG | K12: 0.1 | L12: VT-HV-TT-074 | M12: 10626-051 DG SÂN VẬN ĐỘNG HÙNG VƯƠNG | N12: 29/09/2026 | O12: NGUYEN SONG HUONG | P12: REV0 | R12: Q355B | AB12: 10626-051 | AC12: VT-HV-TT-001-CHANPINX30/Y21-Y22-Q355-SP25-001 | AD12: NEWPLATE
C13: Thép tấm lỡ cỡ cường độ Cao | D13: 6 | E13: 18.62 | F13: KG | L13: VT-HV-TT-074 | M13: 10626-051 DG SÂN VẬN ĐỘNG HÙNG VƯƠNG | N13: 29/09/2026 | O13: NGUYEN SONG HUONG | P13: REV0 | R13: Q355B | S13: 0.09 | T13: 2.38 | U13: 3.43 | V13: 6x264x1500 | AB13: 10626-051 | AC13: VT-HV-TT-001-CHANPINX30/Y21-Y22-Q355-SP25-001 | AD13: NEWPLATE
C14: Thép tấm lỡ cỡ cường độ Cao | D14: 6 | E14: -3.43 | F14: KG | K14: 0.2 | L14: VT-HV-TT-074 | M14: 10626-051 DG SÂN VẬN ĐỘNG HÙNG VƯƠNG | N14: 29/09/2026 | O14: NGUYEN SONG HUONG | P14: REV0 | R14: Q355B | AB14: 10626-051 | AC14: VT-HV-TT-001-CHANPINX30/Y21-Y22-Q355-SP30-001 | AD14: NEWPLATE
C15: Thép tấm lỡ cỡ cường độ Cao | D15: 12 | E15: 102.68 | F15: KG | L15: VT-HV-TT-074 | M15: 10626-051 DG SÂN VẬN ĐỘNG HÙNG VƯƠNG | N15: 29/09/2026 | O15: NGUYEN SONG HUONG | P15: REV0 | R15: Q355B | S15: 0.13 | T15: 11.41 | U15: 72.3 | V15: 12x144x7571 | AB15: 10626-051 | AC15: VT-HV-TT-001-CHANPINX30/Y21-Y22-Q355-SP30-001 | AD15: NEWPLATE
C16: Thép tấm lỡ cỡ cường độ Cao | D16: 12 | E16: -72.3 | F16: KG | K16: 0.3 | L16: VT-HV-TT-074 | M16: 10626-051 DG SÂN VẬN ĐỘNG HÙNG VƯƠNG | N16: 29/09/2026 | O16: NGUYEN SONG HUONG | P16: REV0 | R16: Q355B | AB16: 10626-051 | AC16: VT-HV-TT-001-CHANPINX30/Y21-Y22-Q355-SP30-001 | AD16: NEWPLATE
C17: Thép tấm lỡ cỡ cường độ Cao | D17: 25 | E17: 2653.21 | F17: KG | L17: VT-HV-TT-074 | M17: 10626-051 DG SÂN VẬN ĐỘNG HÙNG VƯƠNG | N17: 29/09/2026 | O17: NGUYEN SONG HUONG | P17: REV0 | R17: Q355B | S17: 1.37 | T17: 17.56 | U17: 2438.03 | V17: 25x2000x6760 | AB17: 10626-051 | AC17: VT-HV-TT-001-CHANPINX30/Y21-Y22-Q355-SP30-001 | AD17: NEWPLATE
C18: Thép tấm lỡ cỡ cường độ Cao | D18: 25 | E18: -2438.03 | F18: KG | K18: 0.4 | L18: VT-HV-TT-074 | M18: 10626-051 DG SÂN VẬN ĐỘNG HÙNG VƯƠNG | N18: 29/09/2026 | O18: NGUYEN SONG HUONG | P18: REV0 | R18: Q355B | AB18: 10626-051 | AC18: VT-HV-TT-001-CHANPINX30/Y21-Y22-Q355-SP30-001 | AD18: NEWPLATE
C19: Thép tấm lỡ cỡ | D19: 20 | E19: 908.09 | F19: KG | K19: VT-10625-051-Z03-1030 | L19: VT-HV-TT-075 | M19: 10626-051 DG SÂN VẬN ĐỘNG HÙNG VƯƠNG | N19: 46032 | O19: PHAN THANH TRUNG | P19: REV0 | R19: Q355 | S19: 5.93 | T19: 54.36 | U19: 0 | V19: 20x482x12000 | AB19: 10626-051 | AC19: VT-HV-TT-001-CHANPINX30/Y21-Y22-Q355-SP30-001 | AD19: NEWPLATE
C20: Thép tấm lỡ cỡ | D20: 20 | E20: 908.09 | F20: KG | K20: VT-10625-051-Z03-1031 | L20: VT-HV-TT-075 | M20: 10626-051 DG SÂN VẬN ĐỘNG HÙNG VƯƠNG | N20: 46032 | O20: PHAN THANH TRUNG | P20: REV0 | R20: Q355 | S20: 5.93 | T20: 54.36 | U20: 0 | V20: 20x482x12000 | AB20: 10626-051 | AC20: VT-HV-TT-001-CHANPINX30/Y21-Y22-Q355-SP30-002 | AD20: NEWPLATE
C21: Thép tấm lỡ cỡ | D21: 20 | E21: 331.58 | F21: KG | K21: VT-10625-051-Z03-1032 | L21: VT-HV-TT-075 | M21: 10626-051 DG SÂN VẬN ĐỘNG HÙNG VƯƠNG | N21: 46032 | O21: PHAN THANH TRUNG | P21: REV0 | R21: Q355 | S21: 1.98 | T21: 47 | U21: 0 | V21: 20x176x12000 | AB21: 10626-051 | AC21: VT-HV-TT-001-CHANPINX30/Y21-Y22-Q355-SP30-002 | AD21: NEWPLATE
C22: Thép tấm lỡ cỡ | D22: 20 | E22: 331.58 | F22: KG | K22: VT-10625-051-Z03-1033 | L22: VT-HV-TT-075 | M22: 10626-051 DG SÂN VẬN ĐỘNG HÙNG VƯƠNG | N22: 46032 | O22: PHAN THANH TRUNG | P22: REV0 | R22: Q355 | S22: 1.98 | T22: 47 | U22: 0 | V22: 20x176x12000 | AB22: 10626-051 | AC22: VT-HV-TT-001-CHANPINX30/Y21-Y22-Q355-SP30-002 | AD22: NEWPLATE
C23: Thép tấm lỡ cỡ | D23: 20 | E23: 274.5 | F23: KG | K23: VT-10625-051-Z03-1034 | L23: VT-HV-TT-075 | M23: 10626-051 DG SÂN VẬN ĐỘNG HÙNG VƯƠNG | N23: 46032 | O23: PHAN THANH TRUNG | P23: REV0 | R23: Q355 | S23: 1.65 | T23: 37.35 | U23: 0 | V23: 20x146x12000 | AB23: 10626-051 | AC23: VT-HV-TT-001-CHANPINX30/Y21-Y22-Q355-SP30-002 | AD23: NEWPLATE
C24: Thép tấm lỡ cỡ | D24: 20 | E24: 331.58 | F24: KG | K24: VT-10625-051-Z03-1035 | L24: VT-HV-TT-075 | M24: 10626-051 DG SÂN VẬN ĐỘNG HÙNG VƯƠNG | N24: 46032 | O24: PHAN THANH TRUNG | P24: REV0 | R24: Q355 | S24: 1.98 | T24: 47 | U24: 0 | V24: 20x176x12000 | AB24: 10626-051 | AC24: VT-HV-TT-001-CHANPINX30/Y21-Y22-Q355-SP30-002 | AD24: NEWPLATE
C25: Thép tấm lỡ cỡ | D25: 20 | E25: 247.64 | F25: KG | K25: VT-10625-051-Z03-1036 | L25: VT-HV-TT-075 | M25: 10626-051 DG SÂN VẬN ĐỘNG HÙNG VƯƠNG | N25: 46032 | O25: PHAN THANH TRUNG | P25: REV0 | R25: Q355 | S25: 1.27 | T25: 64.28 | U25: 0 | V25: 20x136x11598 | AB25: 10626-051 | AC25: VT-HV-TT-001-CHANPINX30/Y21-Y22-Q355-SP30-002 | AD25: NEWPLATE
C26: Thép tấm lỡ cỡ | D26: 20 | E26: 109.12 | F26: KG | K26: VT-10625-051-Z03-1037 | L26: VT-HV-TT-075 | M26: 10626-051 DG SÂN VẬN ĐỘNG HÙNG VƯƠNG | N26: 46032 | O26: PHAN THANH TRUNG | P26: REV0 | R26: Q355 | S26: 0.61 | T26: 21.22 | U26: 0 | V26: 20x125x5560 | AB26: 10626-051 | AC26: VT-HV-TT-001-CHANPINX30/Y21-Y22-Q355-SP30-002 | AD26: NEWPLATE
C27: Thép tấm lỡ cỡ | D27: 20 | E27: 110.07 | F27: KG | K27: VT-10625-051-Z03-1038 | L27: VT-HV-TT-075 | M27: 10626-051 DG SÂN VẬN ĐỘNG HÙNG VƯƠNG | N27: 46032 | O27: PHAN THANH TRUNG | P27: REV0 | R27: Q355 | S27: 0.66 | T27: 15.6 | U27: 0 | V27: 20x176x3983 | AB27: 10626-051 | AC27: VT-HV-TT-001-CHANPINX30/Y21-Y22-Q355-SP30-002 | AD27: NEWPLATE
C28: Thép tấm 40MM Q355B | D28: 2x12 | E28: 1 | F28: TAM | K28: VT-10625-051-Z03-1039 | L28: VT-HV-TT-075 | M28: 10626-051 DG SÂN VẬN ĐỘNG HÙNG VƯƠNG | N28: 46032 | O28: PHAN THANH TRUNG | P28: REV0 | R28: Q355B | S28: 40.69 | T28: 1546.05 | U28: 135.85 | V28: 40x2000x12000 | AB28: 10626-051 | AC28: VT-HV-TT-001-CHANPINX30/Y21-Y22-Q355-SP30-003 | AD28: NEWPLATE
C29: Thép tấm lỡ cỡ cường độ Cao | D29: 40 | E29: -135.85 | F29: KG | K29: VT-10625-051-Z03-1039.1 | L29: VT-HV-TT-075 | M29: 10626-051 DG SÂN VẬN ĐỘNG HÙNG VƯƠNG | N29: 46032 | O29: PHAN THANH TRUNG | P29: REV0 | R29: Q355B | AB29: 10626-051 | AC29: VT-HV-TT-001-CHANPINX30/Y21-Y22-Q355-SP30-003 | AD29: NEWPLATE
C30: Thép tấm lỡ cỡ | D30: 40 | E30: 140.92 | F30: KG | K30: VT-10625-051-Z03-1040 | L30: VT-HV-TT-075 | M30: 10626-051 DG SÂN VẬN ĐỘNG HÙNG VƯƠNG | N30: 46032 | O30: PHAN THANH TRUNG | P30: REV0 | R30: Q355 | S30: 0.69 | T30: 41.7 | U30: 0 | V30: 40x388x1432 | AB30: 10626-051 | AC30: VT-HV-TT-001-CHANPINX30/Y21-Y22-Q355-SP40-001 | AD30: NEWPLATE
C31: Thép tấm lỡ cỡ | D31: 40 | E31: 154.21 | F31: KG | K31: VT-10625-051-Z03-1041 | L31: VT-HV-TT-075 | M31: 10626-051 DG SÂN VẬN ĐỘNG HÙNG VƯƠNG | N31: 46032 | O31: PHAN THANH TRUNG | P31: REV0 | R31: Q355 | S31: 0.69 | T31: 54.99 | U31: 0 | V31: 40x326x1506 | AB31: 10626-051 | AC31: VT-HV-TT-001-CHANPINX30/Y21-Y22-Q355-SP40-001 | AD31: NEWPLATE
C32: Thép tấm lỡ cỡ | D32: 40 | E32: 782.17 | F32: KG | K32: VT-10625-051-Z03-1042 | L32: VT-HV-TT-075 | M32: 10626-051 DG SÂN VẬN ĐỘNG HÙNG VƯƠNG | N32: 46032 | O32: PHAN THANH TRUNG | P32: REV0 | R32: Q355 | S32: 2.51 | T32: 69.95 | U32: 350.53 | V32: 40x500x4987 | AB32: 10626-051 | AC32: VT-HV-TT-001-CHANPINX30/Y21-Y22-Q355-SP40-001 | AD32: NEWPLATE
C33: Thép tấm lỡ cỡ | D33: 40 | E33: -350.53 | F33: KG | K33: VT-10625-051-Z03-1042.1 | L33: VT-HV-TT-075 | M33: 10626-051 DG SÂN VẬN ĐỘNG HÙNG VƯƠNG | N33: 46032 | O33: PHAN THANH TRUNG | P33: REV0 | R33: Q355 | AB33: 10626-051 | AC33: VT-HV-TT-001-CHANPINX30/Y21-Y22-Q355-SP40-001 | AD33: NEWPLATE
C34: Thép tấm lỡ cỡ | D34: 40 | E34: 1183.42 | F34: KG | K34: VT-10625-051-Z03-1043 | L34: VT-HV-TT-075 | M34: 10626-051 DG SÂN VẬN ĐỘNG HÙNG VƯƠNG | N34: 46032 | O34: PHAN THANH TRUNG | P34: REV0 | R34: Q355 | S34: 3.35 | T34: 88.33 | U34: 612.83 | V34: 40x488x8124 | AB34: 10626-051 | AC34: VT-HV-TT-001-CHANPINX30/Y21-Y22-Q355-SP40-001 | AD34: NEWPLATE
C35: Thép tấm lỡ cỡ | D35: 40 | E35: -612.83 | F35: KG | K35: VT-10625-051-Z03-1043.1 | L35: VT-HV-TT-075 | M35: 10626-051 DG SÂN VẬN ĐỘNG HÙNG VƯƠNG | N35: 46032 | O35: PHAN THANH TRUNG | P35: REV0 | R35: Q355 | AB35: 10626-051 | AC35: VT-HV-TT-001-CHANPINX30/Y21-Y22-Q355-SP80-001 | AD35: NEWPLATE
C36: Thép tấm lỡ cỡ | D36: 40 | E36: 1503.88 | F36: KG | K36: VT-10625-051-Z03-1044 | L36: VT-HV-TT-075 | M36: 10626-051 DG SÂN VẬN ĐỘNG HÙNG VƯƠNG | N36: 46032 | O36: PHAN THANH TRUNG | P36: REV0 | R36: Q355 | S36: 4.88 | T36: 148.82 | U36: 653.01 | V36: 40x488x9818 | AB36: 10626-051 | AC36: VT-HV-TT-001-CHANPINX30/Y21-Y22-Q355-SP80-001 | AD36: NEWPLATE
C37: Thép tấm lỡ cỡ | D37: 40 | E37: -653.01 | F37: KG | K37: VT-10625-051-Z03-1044.1 | L37: VT-HV-TT-075 | M37: 10626-051 DG SÂN VẬN ĐỘNG HÙNG VƯƠNG | N37: 46032 | O37: PHAN THANH TRUNG | P37: REV0 | R37: Q355 | AB37: 10626-051 | AC37: VT-HV-TT-001-CHANPINX30/Y21-Y22-Q355-SP80-001 | AD37: NEWPLATE
C38: Thép tấm lỡ cỡ cường độ Cao | D38: 40 | E38: 1670.23 | F38: KG | K38: VT-10625-051-Z03-1045 | L38: VT-HV-TT-075 | M38: 10626-051 DG SÂN VẬN ĐỘNG HÙNG VƯƠNG | N38: 46032 | O38: PHAN THANH TRUNG | P38: REV0 | R38: Q345B | S38: 5.42 | T38: 164.71 | U38: 725.59 | V38: 40x488x10900 | AB38: 10626-051 | AC38: VT-HV-TT-001-CHANPINX30/Y21-Y22-Q355-SP80-001 | AD38: NEWPLATE
C39: Thép tấm lỡ cỡ cường độ Cao | D39: 40 | E39: -725.59 | F39: KG | K39: VT-10625-051-Z03-1045.1 | L39: VT-HV-TT-075 | M39: 10626-051 DG SÂN VẬN ĐỘNG HÙNG VƯƠNG | N39: 46032 | O39: PHAN THANH TRUNG | P39: REV0 | R39: Q345B | AB39: 10626-051 | AC39: VT-HV-TT-001-CHANPINX30/Y21-Y22-Q355-SP80-001 | AD39: NEWPLATE
C40: Thép tấm lỡ cỡ | D40: 40 | E40: 1690.76 | F40: KG | K40: VT-10625-051-Z03-1046 | L40: VT-HV-TT-075 | M40: 10626-051 DG SÂN VẬN ĐỘNG HÙNG VƯƠNG | N40: 46032 | O40: PHAN THANH TRUNG | P40: REV0 | R40: Q355 | S40: 4.83 | T40: 250.07 | U40: 746.13 | V40: 40x494x10900 | AB40: 10626-051 | AC40: VT-HV-TT-001-CHANPINX30/Y21-Y22-Q355-SP80-001 | AD40: NEWPLATE
C41: Thép tấm lỡ cỡ | D41: 40 | E41: -746.13 | F41: KG | K41: VT-10625-051-Z03-1046.1 | L41: VT-HV-TT-075 | M41: 10626-051 DG SÂN VẬN ĐỘNG HÙNG VƯƠNG | N41: 46032 | O41: PHAN THANH TRUNG | P41: REV0 | R41: Q355 | AB41: 10626-051 | AC41: VT-HV-TT-001-CHANPINX30/Y21-Y22-Q355-SP80-001 | AD41: NEWPLATE
...

Sheet  
M2: LỆNH SẢN XUẤT/ PRODUCTION ORDER
A3: CÔNG TRÌNH/ CONSTRUCTION: | C3: ='List chi tiet'!B3&"-"&'List chi tiet'!B2 -> 10626-051-10626-051 DG SÂN VẬN ĐỘNG HÙNG VƯƠNG
A4: LSX/ PRODUCTION ORDER : | C4: =INDEX(M11:M99999, MATCH(1, INDEX(SUBTOTAL(3, OFFSET(M11, ROW(M11:M99999)-ROW(M11), 0)), 0), 0)) -> VT-HV-TT-001
A5: Hạng mục/ Items: | C5: =INDEX(P11:P99999, MATCH(1, INDEX(SUBTOTAL(3, OFFSET(P11, ROW(P11:P99999)-ROW(P11), 0)), 0), 0)) -> PIN MB1 PIN2 (X30/Y21-Y22)
A6: Đơn vị gia công/ Processing unit: | C6: SC-VT1
A7: Lệnh xuất:
A8: Lệnh thu lỡ cỡ: | H8: =SUBTOTAL(9, H11:H99999) -> 12 | I8: =SUBTOTAL(9, I11:I99999) -> 2260.8 | P8: =SUMPRODUCT(SUBTOTAL(103,OFFSET(B11,ROW(B11:B99692)-MIN(ROW(B11:B99692)),,1)),--(B11:B99692<>"")) -> 1
A9: Lệnh Thu phế liệu: | AC9: =IFERROR(VLOOKUP(A9,'List chi tiet'!$A:$L,12,0),"")
A10: STT/ No. | B10: Tên/ mã số Name/code | C10: Dày/ Thickness | D10: Rộng/ Width | E10: Dài/ Length | F10: Mác thép/ Steel mark | G10: ĐVT/ Unit | H10: SL / Qty | I10: Khối lượng/ Weight (kg) | J10: ĐV CẮT | K10: Đơn Vị Gia Công | L10: Đơn Vị Nhận | M10: LSX | N10: Lưu ý | O10: Có Lỗ | P10: Hạng Mục | Q10: Cánh Bụng bản mã | R10: Nguyên Khổ | S10: Lỡ Cỡ | T10: Tận Dụng | U10: Chấn Bend | V10: Vát Mép | W10: Lần Ban Hành | X10: Ngày B.hành | Y10: Note | Z10: REV01 | AA10: REV02 | AB10: Mã Dự Án | AC10: NESTING | AD10: Nguồn Gốc Vật Tư
A11: =IF('List chi tiet'!A6<>"",'List chi tiet'!A6,"") -> 1 | B11: =IF('List chi tiet'!B6<>"",'List chi tiet'!B6,"") -> BA1 | C11: =IF('List chi tiet'!E6<>"",'List chi tiet'!E6,"") -> 25 | D11: =IF('List chi tiet'!F6<>"",'List chi tiet'!F6,"") -> 80 | E11: =IF('List chi tiet'!G6<>"",'List chi tiet'!G6,"") -> 12000 | F11: =IF('List chi tiet'!C6<>"",'List chi tiet'!C6,"") -> Q355 | G11: =IF(A11<>"","Pcs","") -> Pcs | H11: =IF('List chi tiet'!H6<>"",'List chi tiet'!H6,"") -> 12 | I11: =IF('List chi tiet'!J6<>"",'List chi tiet'!J6,"") -> 2260.8 | J11: =IF(A11<>"","SC-VT1","") -> SC-VT1 | M11: =IF('List chi tiet'!A6<>"",LEFT('List chi tiet'!L6,FIND("-",'List chi tiet'!L6,FIND("-",'List chi tiet'!L6,FIND("-",'List chi tiet'!L6,FIND("-",'List chi tiet'!L6)+1)+1)+1)-1),"") -> VT-HV-TT-001 | N11: =IF('List chi tiet'!D6<>"",'List chi tiet'!D6,"") -> PL25x80x12000 | P11: =IF('List chi tiet'!Z6<>"",'List chi tiet'!Z6,"") -> PIN MB1 PIN2 (X30/Y21-Y22) | W11: =IF('List chi tiet'!Q6<>"",'List chi tiet'!Q6,"") -> 1 | X11: =IF('List chi tiet'!R6<>"",'List chi tiet'!R6,"") -> 06/07/2026 | AB11: =IF('List chi tiet'!V6<>"",'List chi tiet'!V6,"") -> 10626-051 | AC11: =IF('List chi tiet'!L6<>"",'List chi tiet'!L6,"") -> VT-HV-TT-001-CHANPINX30/Y21-Y22-Q355-SP25-001 | AD11: =IF('List chi tiet'!K6<>"",'List chi tiet'!K6,"") -> PL25x2200x12000
